<?xml version="1.0"?>
<sdf version="1.8">
    <world name="Moving_robot">
        <physics name="1ms" type="ignored">
            <max_step_size>0.001</max_step_size>
            <real_time_factor>1.0</real_time_factor>
        </physics>
        <plugin
            filename="libignition-gazebo-physics-system.so"
            name="ignition::gazebo::systems::Physics">
        </plugin>
        <plugin
            filename="libignition-gazebo-user-commands-system.so"
            name="ignition::gazebo::systems::UserCommands">
        </plugin>
        <plugin
            filename="libignition-gazebo-scene-broadcaster-system.so"
            name="ignition::gazebo::systems::SceneBroadcaster">
        </plugin>
        <plugin filename="libignition-gazebo-imu-system.so"
            name="ignition::gazebo::systems::Imu">
        </plugin>
        <plugin filename="libignition-gazebo-contact-system.so"
            name="ignition::gazebo::systems::Contact">
        </plugin>

        <plugin filename="libignition-gazebo-imu-system.so"
            name="ignition::gazebo::systems::Imu">
        </plugin>

        <plugin filename="ignition-gazebo-sensors-system"
            name="ignition::gazebo::systems::Sensors">
            <render_engine>ogre2</render_engine>
        </plugin>

        <light type="directional" name="sun">
            <cast_shadows>true</cast_shadows>
            <pose>0 0 10 0 0 0</pose>
            <diffuse>0.8 0.8 0.8 1</diffuse>
            <specular>0.2 0.2 0.2 1</specular>
            <attenuation>
                <range>1000</range>
                <constant>0.9</constant>
                <linear>0.01</linear>
                <quadratic>0.001</quadratic>
            </attenuation>
            <direction>-0.5 0.1 -0.9</direction>
        </light>

        <model name="ground_plane">
            <static>true</static>
            <link name="link">
                <collision name="collision">
                    <geometry>
                        <plane>
                            <normal>0 0 1</normal>
                        </plane>
                    </geometry>
                </collision>
                <visual name="visual">
                    <geometry>
                        <plane>
                            <normal>0 0 1</normal>
                            <size>100 100</size>
                        </plane>
                    </geometry>
                    <material>
                        <ambient>0.8 0.8 0.8 1</ambient>
                        <diffuse>0.8 0.8 0.8 1</diffuse>
                        <specular>0.8 0.8 0.8 1</specular>
                    </material>
                </visual>
            </link>
        </model>

        <model name="finns_car" canonical_link="chassis">
            <pose relative_to='world'>0 0 0 0 0 0</pose>
            <link name="chassis">
                <pose relative_to="__model__">0 0 0.35 0 0 0</pose>
                <!-- TODO: Make this accurate -->
                <inertial> <!--inertial
                    properties of the link mass, inertia matix-->
                    <mass>1.14395</mass>
                    <inertia>
                        <ixx>0.095329</ixx>
                        <ixy>0</ixy>
                        <ixz>0</ixz>
                        <iyy>0.381317</iyy>
                        <iyz>0</iyz>
                        <izz>0.476646</izz>
                    </inertia>
                </inertial>
                <visual name='visual'>
                    <geometry>
                        <box>
                            <size>1.0 0.5 0.20</size>
                        </box>
                    </geometry>
                    <!--let's
                    add color to our link-->
                    <material>
                        <ambient>0.0 0.0 1.0 1</ambient>
                        <diffuse>0.0 0.0 1.0 1</diffuse>
                        <specular>0.0 0.0 1.0 1</specular>
                    </material>
                </visual>
                <collision name='collision'>
                    <geometry>
                        <box>
                            <size>1.0 0.5 0.5</size>
                        </box>
                    </geometry>
                </collision>
            </link>

            <frame name="front_left_frame" attached_to='chassis'>
                <pose>0.35 0.175 -0.10 0 0 0</pose>
            </frame>
            <link name='front_left_wheel'>
                <pose relative_to="front_left_frame">0 0 -0.15 -1.57 0 0</pose>
                <inertial>
                    <mass>1</mass>
                    <inertia>
                        <ixx>0.043333</ixx>
                        <ixy>0</ixy>
                        <ixz>0</ixz>
                        <iyy>0.043333</iyy>
                        <iyz>0</iyz>
                        <izz>0.08</izz>
                    </inertia>
                </inertial>
                <visual name='visual'>
                    <geometry>
                        <cylinder>
                            <radius>0.1</radius>
                            <length>0.05</length>
                        </cylinder>
                    </geometry>
                    <material>
                        <ambient>1.0 0.0 0.0 1</ambient>
                        <diffuse>1.0 0.0 0.0 1</diffuse>
                        <specular>1.0 0.0 0.0 1</specular>
                    </material>
                </visual>
                <collision name='collision'>
                    <geometry>
                        <cylinder>
                            <radius>0.1</radius>
                            <length>0.05</length>
                        </cylinder>
                    </geometry>
                </collision>
            </link>
            <link name='front_left'>
                <pose relative_to="front_left_frame">0 0 0 0 0 0</pose>
                <inertial>
                    <mass>1</mass>
                    <inertia>
                        <ixx>0.043333</ixx>
                        <ixy>0</ixy>
                        <ixz>0</ixz>
                        <iyy>0.043333</iyy>
                        <iyz>0</iyz>
                        <izz>0.08</izz>
                    </inertia>
                </inertial>
                <visual name='visual'>
                    <geometry>
                        <cylinder>
                            <radius>0.1</radius>
                            <length>0.05</length>
                        </cylinder>
                    </geometry>
                    <material>
                        <ambient>1.0 0.0 0.0 1</ambient>
                        <diffuse>1.0 0.0 0.0 1</diffuse>
                        <specular>1.0 0.0 0.0 1</specular>
                    </material>
                </visual>
                <collision name='collision'>
                    <geometry>
                        <cylinder>
                            <radius>0.1</radius>
                            <length>0.05</length>
                        </cylinder>
                    </geometry>
                </collision>
            </link>
            <joint name="front_left_wheel_joint" type="revolute">
                <pose relative_to="front_left_frame">0 0 -0.15 -1.57 0 0</pose>
                <parent>front_left</parent>
                <child>front_left_wheel</child>
                <axis>
                    <xyz expressed_in='__model__'>0 1 0</xyz> <!--can
                    be defined as any frame or even arbitrary frames-->
                    <limit>
                        <lower>-1.79769e+308</lower>    <!--negative
                        infinity-->
                        <upper>1.79769e+308</upper>     <!--positive
                        infinity-->
                    </limit>
                </axis>
            </joint>
            <joint name="front_left_joint" type="revolute">
                <pose relative_to="front_left_frame" />
                <parent>chassis</parent>
                <child>front_left</child>
                <axis>
                    <xyz expressed_in='__model__'>0 0 1</xyz> <!--can
                    be defined as any frame or even arbitrary frames-->
                    <limit>
                        <lower>-1.79769e+308</lower>    <!--negative
                        infinity-->
                        <upper>1.79769e+308</upper>     <!--positive
                        infinity-->
                    </limit>
                </axis>
            </joint>

            <frame name="front_right_frame" attached_to='chassis'>
                <pose>0.35 -0.175 -0.10 0 0 0</pose>
            </frame>
            <link name='front_right_wheel'>
                <pose relative_to="front_right_frame">0 0 -0.15 -1.57 0 0</pose>
                <inertial>
                    <mass>1</mass>
                    <inertia>
                        <ixx>0.043333</ixx>
                        <ixy>0</ixy>
                        <ixz>0</ixz>
                        <iyy>0.043333</iyy>
                        <iyz>0</iyz>
                        <izz>0.08</izz>
                    </inertia>
                </inertial>
                <visual name='visual'>
                    <geometry>
                        <cylinder>
                            <radius>0.1</radius>
                            <length>0.05</length>
                        </cylinder>
                    </geometry>
                    <material>
                        <ambient>1.0 0.0 0.0 1</ambient>
                        <diffuse>1.0 0.0 0.0 1</diffuse>
                        <specular>1.0 0.0 0.0 1</specular>
                    </material>
                </visual>
                <collision name='collision'>
                    <geometry>
                        <cylinder>
                            <radius>0.1</radius>
                            <length>0.05</length>
                        </cylinder>
                    </geometry>
                </collision>
            </link>
            <link name='front_right'>
                <pose relative_to="front_right_frame">0 0 0 0 0 0</pose>
                <inertial>
                    <mass>1</mass>
                    <inertia>
                        <ixx>0.043333</ixx>
                        <ixy>0</ixy>
                        <ixz>0</ixz>
                        <iyy>0.043333</iyy>
                        <iyz>0</iyz>
                        <izz>0.08</izz>
                    </inertia>
                </inertial>
                <visual name='visual'>
                    <geometry>
                        <cylinder>
                            <radius>0.1</radius>
                            <length>0.05</length>
                        </cylinder>
                    </geometry>
                    <material>
                        <ambient>1.0 0.0 0.0 1</ambient>
                        <diffuse>1.0 0.0 0.0 1</diffuse>
                        <specular>1.0 0.0 0.0 1</specular>
                    </material>
                </visual>
                <collision name='collision'>
                    <geometry>
                        <cylinder>
                            <radius>0.1</radius>
                            <length>0.05</length>
                        </cylinder>
                    </geometry>
                </collision>
            </link>
            <joint name="front_right_wheel_joint" type="revolute">
                <pose relative_to="front_right_frame">0 0 -0.15 -1.57 0 0</pose>
                <parent>front_right</parent>
                <child>front_right_wheel</child>
                <axis>
                    <xyz expressed_in='__model__'>0 1 0</xyz> <!--can
                    be defined as any frame or even arbitrary frames-->
                    <limit>
                        <lower>-1.79769e+308</lower>    <!--negative
                        infinity-->
                        <upper>1.79769e+308</upper>     <!--positive
                        infinity-->
                    </limit>
                </axis>
            </joint>
            <joint name="front_right_joint" type="revolute">
                <pose relative_to="front_right_frame" />
                <parent>chassis</parent>
                <child>front_right</child>
                <axis>
                    <xyz expressed_in='__model__'>0 0 1</xyz> <!--can
                    be defined as any frame or even arbitrary frames-->
                    <limit>
                        <lower>-1.79769e+308</lower>    <!--negative
                        infinity-->
                        <upper>1.79769e+308</upper>     <!--positive
                        infinity-->
                    </limit>
                </axis>
            </joint>

            <frame name="back_right_frame" attached_to='chassis'>
                <pose>-0.35 -0.175 -0.10 0 0 0</pose>
            </frame>
            <link name='back_right_wheel'>
                <pose relative_to="back_right_frame">0 0 -0.15 -1.57 0 0</pose>
                <inertial>
                    <mass>1</mass>
                    <inertia>
                        <ixx>0.043333</ixx>
                        <ixy>0</ixy>
                        <ixz>0</ixz>
                        <iyy>0.043333</iyy>
                        <iyz>0</iyz>
                        <izz>0.08</izz>
                    </inertia>
                </inertial>
                <visual name='visual'>
                    <geometry>
                        <cylinder>
                            <radius>0.1</radius>
                            <length>0.05</length>
                        </cylinder>
                    </geometry>
                    <material>
                        <ambient>1.0 0.0 0.0 1</ambient>
                        <diffuse>1.0 0.0 0.0 1</diffuse>
                        <specular>1.0 0.0 0.0 1</specular>
                    </material>
                </visual>
                <collision name='collision'>
                    <geometry>
                        <cylinder>
                            <radius>0.1</radius>
                            <length>0.05</length>
                        </cylinder>
                    </geometry>
                </collision>
            </link>
            <link name='back_right'>
                <pose relative_to="back_right_frame">0 0 0 0 0 0</pose>
                <inertial>
                    <mass>1</mass>
                    <inertia>
                        <ixx>0.043333</ixx>
                        <ixy>0</ixy>
                        <ixz>0</ixz>
                        <iyy>0.043333</iyy>
                        <iyz>0</iyz>
                        <izz>0.08</izz>
                    </inertia>
                </inertial>
                <visual name='visual'>
                    <geometry>
                        <cylinder>
                            <radius>0.1</radius>
                            <length>0.05</length>
                        </cylinder>
                    </geometry>
                    <material>
                        <ambient>1.0 0.0 0.0 1</ambient>
                        <diffuse>1.0 0.0 0.0 1</diffuse>
                        <specular>1.0 0.0 0.0 1</specular>
                    </material>
                </visual>
                <collision name='collision'>
                    <geometry>
                        <cylinder>
                            <radius>0.1</radius>
                            <length>0.05</length>
                        </cylinder>
                    </geometry>
                </collision>
            </link>
            <joint name="back_right_joint" type="revolute">
                <pose relative_to="back_right_frame">0 0 -0.15 -1.57 0 0</pose>
                <parent>back_right</parent>
                <child>back_right_wheel</child>
                <axis>
                    <xyz expressed_in='__model__'>0 1 0</xyz> <!--can
                    be defined as any frame or even arbitrary frames-->
                    <limit>
                        <lower>-1.79769e+308</lower>    <!--negative
                        infinity-->
                        <upper>1.79769e+308</upper>     <!--positive
                        infinity-->
                    </limit>
                </axis>
            </joint>
            <joint name="back_right_wheel_joint" type="fixed">
                <pose relative_to="back_right_frame" />
                <parent>chassis</parent>
                <child>back_right</child>
                <axis>
                    <xyz expressed_in='__model__'>0 0 1</xyz> <!--can
                    be defined as any frame or even arbitrary frames-->
                    <limit>
                        <lower>-1.79769e+308</lower>    <!--negative
                        infinity-->
                        <upper>1.79769e+308</upper>     <!--positive
                        infinity-->
                    </limit>
                </axis>
            </joint>

            <frame name="back_left_frame" attached_to='chassis'>
                <pose>-0.35 0.175 -0.10 0 0 0</pose>
            </frame>
            <link name='back_left_wheel'>
                <pose relative_to="back_left_frame">0 0 -0.15 -1.57 0 0</pose>
                <inertial>
                    <mass>1</mass>
                    <inertia>
                        <ixx>0.043333</ixx>
                        <ixy>0</ixy>
                        <ixz>0</ixz>
                        <iyy>0.043333</iyy>
                        <iyz>0</iyz>
                        <izz>0.08</izz>
                    </inertia>
                </inertial>
                <visual name='visual'>
                    <geometry>
                        <cylinder>
                            <radius>0.1</radius>
                            <length>0.05</length>
                        </cylinder>
                    </geometry>
                    <material>
                        <ambient>1.0 0.0 0.0 1</ambient>
                        <diffuse>1.0 0.0 0.0 1</diffuse>
                        <specular>1.0 0.0 0.0 1</specular>
                    </material>
                </visual>
                <collision name='collision'>
                    <geometry>
                        <cylinder>
                            <radius>0.1</radius>
                            <length>0.05</length>
                        </cylinder>
                    </geometry>
                </collision>
            </link>
            <link name='back_left'>
                <pose relative_to="back_left_frame">0 0 0 0 0 0</pose>
                <inertial>
                    <mass>1</mass>
                    <inertia>
                        <ixx>0.043333</ixx>
                        <ixy>0</ixy>
                        <ixz>0</ixz>
                        <iyy>0.043333</iyy>
                        <iyz>0</iyz>
                        <izz>0.08</izz>
                    </inertia>
                </inertial>
                <visual name='visual'>
                    <geometry>
                        <cylinder>
                            <radius>0.1</radius>
                            <length>0.05</length>
                        </cylinder>
                    </geometry>
                    <material>
                        <ambient>1.0 0.0 0.0 1</ambient>
                        <diffuse>1.0 0.0 0.0 1</diffuse>
                        <specular>1.0 0.0 0.0 1</specular>
                    </material>
                </visual>
                <collision name='collision'>
                    <geometry>
                        <cylinder>
                            <radius>0.1</radius>
                            <length>0.05</length>
                        </cylinder>
                    </geometry>
                </collision>
            </link>
            <joint name="back_left_joint" type="revolute">
                <pose relative_to="back_left_frame">0 0 -0.15 -1.57 0 0</pose>
                <parent>back_left</parent>
                <child>back_left_wheel</child>
                <axis>
                    <xyz expressed_in='__model__'>0 1 0</xyz> <!--can
                    be defined as any frame or even arbitrary frames-->
                    <limit>
                        <lower>-1.79769e+308</lower>    <!--negative
                        infinity-->
                        <upper>1.79769e+308</upper>     <!--positive
                        infinity-->
                    </limit>
                </axis>
            </joint>
            <joint name="back_left_wheel_joint" type="fixed">
                <pose relative_to="back_left_frame" />
                <parent>chassis</parent>
                <child>back_left</child>
                <axis>
                    <xyz expressed_in='__model__'>0 0 1</xyz> <!--can
                    be defined as any frame or even arbitrary frames-->
                    <limit>
                        <lower>-1.79769e+308</lower>    <!--negative
                        infinity-->
                        <upper>1.79769e+308</upper>     <!--positive
                        infinity-->
                    </limit>
                </axis>
            </joint>

            <plugin
                filename="libignition-gazebo-ackermann-steering-system.so"
                name="ignition::gazebo::systems::AckermannSteering">
                <left_joint>front_left_wheel_joint</left_joint>
                <right_joint>front_right_wheel_joint</right_joint>
                <left_joint>back_left_wheel_joint</left_joint>
                <right_joint>back_right_wheel_joint</right_joint>
                <left_steering_joint>front_left_joint</left_steering_joint>
                <right_steering_joint>front_right_joint</right_steering_joint>
                <wheel_separation>0.35</wheel_separation>
                <kingpin_width>0.30</kingpin_width>
                <wheel_base>0.7</wheel_base>
                <wheel_radius>0.1</wheel_radius>
                <steering_limit>1.57</steering_limit>
                <odom_publish_frequency>1</odom_publish_frequency>
                <topic>cmd_vel</topic>
            </plugin>

        </model>


        <model name='wall'>
            <static>true</static>
            <pose>5 0 0 0 0 0</pose><!--pose
            relative to the world-->

            <plugin filename="libignition-gazebo-touchplugin-system.so"
                name="ignition::gazebo::systems::TouchPlugin">
                <target>vehicle_blue</target>
                <namespace>wall</namespace>
                <time>0.001</time>
                <enabled>true</enabled>
            </plugin>
            <link name='box'>
                <sensor name='sensor_contact' type='contact'>
                    <contact>
                        <collision>collision</collision>
                    </contact>
                </sensor>
                <pose />
                <visual name='visual'>
                    <geometry>
                        <box>
                            <size>0.5 10.0 2.0</size>
                        </box>
                    </geometry>
                    <!--let's
                    add color to our link-->
                    <material>
                        <ambient>0.0 0.0 1.0 1</ambient>
                        <diffuse>0.0 0.0 1.0 1</diffuse>
                        <specular>0.0 0.0 1.0 1</specular>
                    </material>
                </visual>
                <collision name='collision'>
                    <geometry>
                        <box>
                            <size>0.5 10.0 2.0</size>
                        </box>
                    </geometry>
                </collision>
            </link>
        </model>

        <!-- Moving Forward-->
        <plugin filename="libignition-gazebo-triggered-publisher-system.so"
            name="ignition::gazebo::systems::TriggeredPublisher">
            <input type="ignition.msgs.Int32" topic="/keyboard/keypress">
                <match field="data">16777235</match>
            </input>
            <output type="ignition.msgs.Twist" topic="/cmd_vel">
                linear: {x: 0.5}, angular: {z: 0.0}
            </output>
        </plugin>

        <!-- Moving Backward-->
        <plugin filename="libignition-gazebo-triggered-publisher-system.so"
            name="ignition::gazebo::systems::TriggeredPublisher">
            <input type="ignition.msgs.Int32" topic="/keyboard/keypress">
                <match field="data">16777237</match>
            </input>
            <output type="ignition.msgs.Twist" topic="/cmd_vel">
                linear: {x: -0.5}, angular: {z: 0.0}
            </output>
        </plugin>

        <!-- Rotating right-->
        <plugin filename="libignition-gazebo-triggered-publisher-system.so"
            name="ignition::gazebo::systems::TriggeredPublisher">
            <input type="ignition.msgs.Int32" topic="/keyboard/keypress">
                <match field="data">16777236</match>
            </input>
            <output type="ignition.msgs.Twist" topic="/cmd_vel">
                linear: {x: 0.0}, angular: {z: -0.5}
            </output>
        </plugin>

        <!--Rotating
        left-->
        <plugin filename="libignition-gazebo-triggered-publisher-system.so"
            name="ignition::gazebo::systems::TriggeredPublisher">
            <input type="ignition.msgs.Int32" topic="/keyboard/keypress">
                <match field="data">16777234</match>
            </input>
            <output type="ignition.msgs.Twist" topic="/cmd_vel">
                linear: {x: 0.0}, angular: {z: 0.5}
            </output>
        </plugin>
    </world>
</sdf>
